<?xml version="1.0" ?>
<!-- =================================================================================== -->
<!-- |    This document was autogenerated by xacro from automation_robot_description.urdf.xacro | -->
<!-- |    EDITING THIS FILE BY HAND IS NOT RECOMMENDED                                 | -->
<!-- =================================================================================== -->
<robot name="isi_robot">
  <!-- ****************** ROBOT BASE FOOTPRINT ***************************  -->
  <!-- Define the center of the main robot chassis projected on the ground -->
  <link name="base_footprint"/>
  <!-- The base footprint of the robot is located underneath the chassis -->
  <joint name="base_joint" type="fixed">
    <parent link="base_footprint"/>
    <child link="base_link"/>
    <origin rpy="0 0 0" xyz="0.0 0.0 0.19"/>
  </joint>
  <!-- ********************** ROBOT BASE *********************************  -->
  <link name="base_link">
    <visual>
      <origin rpy="0.0 0 0.0" xyz="0 0 0.0"/>
      <geometry>
        <box size="0.7 0.39 0.2"/>
      </geometry>
      <material name="Red">
        <color rgba="1.0 0.0 0.0 1.0"/>
      </material>
    </visual>
    <collision>
      <geometry>
        <box size="0.7 0.39 0.2"/>
      </geometry>
    </collision>
    <inertial>
      <origin rpy="1.5707963267948966 0 1.5707963267948966" xyz="0 0 0"/>
      <mass value="40.0"/>
      <inertia ixx="1.7666666666666664" ixy="0.0" ixz="0.0" iyy="2.140333333333333" iyz="0.0" izz="0.6403333333333334"/>
    </inertial>
  </link>
  <!-- *********************** DRIVE WHEELS ******************************  -->
  <link name="drivewhl_l_link">
    <visual>
      <origin rpy="1.5707963267949 0 0" xyz="0 0 0"/>
      <geometry>
        <cylinder length="0.06" radius="0.14"/>
      </geometry>
      <material name="White">
        <color rgba="1.0 1.0 1.0 1.0"/>
      </material>
    </visual>
    <collision>
      <origin rpy="1.5707963267948966 0 0" xyz="0 0 0"/>
      <geometry>
        <cylinder length="0.06" radius="0.14"/>
      </geometry>
    </collision>
    <inertial>
      <origin rpy="1.5707963267948966 0 0" xyz="0 0 0"/>
      <mass value="110.5"/>
      <inertia ixx="0.5746000000000001" ixy="0" ixz="0" iyy="0.5746000000000001" iyz="0" izz="1.0829000000000002"/>
    </inertial>
  </link>
  <!-- Connect the wheels to the base_link at the appropriate location, and 
         define a continuous joint to allow the wheels to freely rotate about
         an axis -->
  <joint name="drivewhl_l_joint" type="revolute">
    <parent link="base_link"/>
    <child link="drivewhl_l_link"/>
    <origin rpy="0 0 0" xyz="-0.221 0.23 -0.05"/>
    <limit effort="30" lower="-1.79769e+308" upper="1.79769e+308" velocity="5.0"/>
    <axis xyz="0 1 0"/>
  </joint>
  <link name="drivewhl_r_link">
    <visual>
      <origin rpy="1.5707963267949 0 0" xyz="0 0 0"/>
      <geometry>
        <cylinder length="0.06" radius="0.14"/>
      </geometry>
      <material name="White">
        <color rgba="1.0 1.0 1.0 1.0"/>
      </material>
    </visual>
    <collision>
      <origin rpy="1.5707963267948966 0 0" xyz="0 0 0"/>
      <geometry>
        <cylinder length="0.06" radius="0.14"/>
      </geometry>
    </collision>
    <inertial>
      <origin rpy="1.5707963267948966 0 0" xyz="0 0 0"/>
      <mass value="110.5"/>
      <inertia ixx="0.5746000000000001" ixy="0" ixz="0" iyy="0.5746000000000001" iyz="0" izz="1.0829000000000002"/>
    </inertial>
  </link>
  <!-- Connect the wheels to the base_link at the appropriate location, and 
         define a continuous joint to allow the wheels to freely rotate about
         an axis -->
  <joint name="drivewhl_r_joint" type="revolute">
    <parent link="base_link"/>
    <child link="drivewhl_r_link"/>
    <origin rpy="0 0 0" xyz="-0.221 -0.23 -0.05"/>
    <limit effort="30" lower="-1.79769e+308" upper="1.79769e+308" velocity="5.0"/>
    <axis xyz="0 1 0"/>
  </joint>
  <!-- *********************** CASTER WHEEL ******************************  -->
  <!-- We add a caster wheel. It will be modeled as sphere.
       We define the wheel’s geometry, material and the joint to connect it to 
       base_link at the appropriate location. -->
  <link name="front_caster">
    <visual>
      <geometry>
        <sphere radius="0.09"/>
      </geometry>
      <material name="White">
        <color rgba="1.0 1.0 1.0 1.0"/>
      </material>
    </visual>
    <collision>
      <origin rpy="0 0 0" xyz="0 0 0"/>
      <geometry>
        <sphere radius="0.09"/>
      </geometry>
    </collision>
    <inertial>
      <mass value="10.05"/>
      <inertia ixx="0.032562" ixy="0.0" ixz="0.0" iyy="0.032562" iyz="0.0" izz="0.032562"/>
    </inertial>
  </link>
  <gazebo reference="front_caster">
    <mu1>0.01</mu1>
    <mu2>0.01</mu2>
  </gazebo>
  <joint name="caster_joint" type="fixed">
    <parent link="base_link"/>
    <child link="front_caster"/>
    <origin rpy="0 0 0" xyz="0.217 0.0 -0.1"/>
  </joint>
  <!-- *********************** IMU SETUP *********************************  -->
  <!-- Each sensor must be attached to a link.                              -->
  <joint name="imu_joint" type="fixed">
    <parent link="base_link"/>
    <child link="imu_link"/>
    <origin rpy="0 0 0" xyz="-0.10 0 0.05"/>
  </joint>
  <link name="imu_link"/>
  <!-- *********************** GPS SETUP **********************************  -->
  <joint name="gps_joint" type="fixed">
    <parent link="base_link"/>
    <child link="gps_link"/>
    <origin rpy="0 0 0" xyz="0.10 0 0.05"/>
  </joint>
  <link name="gps_link"/>
  <!-- *********************  LIDAR SETUP ******************************** -->
  <!-- LiDAR Link -->
  <link name="lidar_link">
    <visual>
      <geometry>
        <box size="0.025 0.025 0.025"/>
      </geometry>
      <material name="Blue">
        <color rgba="0 0 1 1.0"/>
      </material>
    </visual>
    <collision>
      <geometry>
        <box size="0.025 0.025 0.025"/>
      </geometry>
    </collision>
    <inertial>
      <mass value="0.1"/>
      <inertia ixx="0.000166667" ixy="0.0" ixz="0.0" iyy="0.000166667" iyz="0.0" izz="0.000166667"/>
    </inertial>
  </link>
  <!-- LiDAR Joint -->
  <joint name="lidar_joint" type="fixed">
    <parent link="base_link"/>
    <child link="lidar_link"/>
    <!--origin xyz="0.0 0.0 ${(-wheel_radius+wheel_zoff)}" rpy="0 1.57 0"/-->
    <origin rpy="0 1.57 0" xyz="0.0 0.0 -0.1125"/>
  </joint>
  <gazebo reference="lidar_link">
    <sensor name="lidar_sensor" type="gpu_ray">
      <topic>/lidar</topic>
      <!--pose>z y x r p y</pose-->
      <pose>0.0 0 0 0 0 0</pose>
      <visualize>true</visualize>
      <update_rate>10</update_rate>
      <ray>
        <scan>
          <horizontal>
            <samples>1</samples>
            <resolution>1</resolution>
            <min_angle>0</min_angle>
            <max_angle>0</max_angle>
          </horizontal>
          <vertical>
            <samples>1</samples>
            <resolution>1</resolution>
            <min_angle>0</min_angle>
            <max_angle>0</max_angle>
          </vertical>
        </scan>
        <range>
          <min>0.01</min>
          <max>10.0</max>
          <resolution>0.01</resolution>
        </range>
        <noise>
          <type>gaussian</type>
          <mean>0.0</mean>
          <stddev>0.01</stddev>
        </noise>
      </ray>
      
      <plugin filename="libignition-gazebo-sensors-system.so" name="ignition::gazebo::systems::Sensors">
		   <topicName>/lidar</topicName>
		   <frameName>lidar_link</frameName>
		</plugin>
    </sensor>
  </gazebo>
  <!-- *********************  Gazebo Plugin - Diff Drive ******************************** -->
  <gazebo>
    <plugin filename="ignition-gazebo-diff-drive-system" name="ignition::gazebo::systems::DiffDrive">
      <left_joint>drivewhl_l_joint</left_joint>
      <right_joint>drivewhl_r_joint</right_joint>
      <wheel_separation>0.7</wheel_separation>
      <wheel_radius>0.14</wheel_radius>
      <odom_publish_frequency>1</odom_publish_frequency>
      <topic>/cmd_vel</topic>
    </plugin>
  </gazebo>
  <!-- *********************  Gazebo Plugin - Magnetic Force ******************************** -->
  <gazebo>
	<plugin name="magnetic_adhesion_plugin" filename="libmagnetic_adhesion_plugin.so"/>
  </gazebo>
</robot>
